<?xml version="1.0" encoding="UTF-8"?>
<!-- Generated by org.testng.reporters.JUnitReportReporter -->
<testsuite hostname="LTCH-B3J24253GP" failures="0" tests="1" name="practice_selenium.Revision" time="0.000" errors="1" timestamp="2024-10-26T15:39:32 IST" skipped="0">
  <testcase classname="practice_selenium.Revision" name="mainTest" time="0.000">
    <error message="
Cannot instantiate class practice_selenium.DataProviders" type="org.testng.TestNGException">
      <![CDATA[org.testng.TestNGException: 
Cannot instantiate class practice_selenium.DataProviders
at org.testng.internal.InstanceCreator.newInstance(InstanceCreator.java:36)
at org.testng.internal.Parameters.findDataProvider(Parameters.java:654)
at org.testng.internal.Parameters.findDataProvider(Parameters.java:555)
at org.testng.internal.Parameters.handleParameters(Parameters.java:776)
at org.testng.internal.Parameters.handleParameters(Parameters.java:744)
at org.testng.internal.ParameterHandler.handleParameters(ParameterHandler.java:59)
at org.testng.internal.ParameterHandler.createParameters(ParameterHandler.java:38)
at org.testng.internal.TestInvoker$MethodInvocationAgent.invoke(TestInvoker.java:783)
at org.testng.internal.TestInvoker.invokeTestMethods(TestInvoker.java:146)
at org.testng.internal.TestMethodWorker.invokeTestMethods(TestMethodWorker.java:146)
at org.testng.internal.TestMethodWorker.run(TestMethodWorker.java:128)
at java.base/java.util.ArrayList.forEach(ArrayList.java:1596)
at org.testng.TestRunner.privateRun(TestRunner.java:766)
at org.testng.TestRunner.run(TestRunner.java:587)
at org.testng.SuiteRunner.runTest(SuiteRunner.java:384)
at org.testng.SuiteRunner.runSequentially(SuiteRunner.java:378)
at org.testng.SuiteRunner.privateRun(SuiteRunner.java:337)
at org.testng.SuiteRunner.run(SuiteRunner.java:286)
at org.testng.SuiteRunnerWorker.runSuite(SuiteRunnerWorker.java:53)
at org.testng.SuiteRunnerWorker.run(SuiteRunnerWorker.java:96)
at org.testng.TestNG.runSuitesSequentially(TestNG.java:1187)
at org.testng.TestNG.runSuitesLocally(TestNG.java:1109)
at org.testng.TestNG.runSuites(TestNG.java:1039)
at org.testng.TestNG.run(TestNG.java:1007)
at org.testng.remote.AbstractRemoteTestNG.run(AbstractRemoteTestNG.java:115)
at org.testng.remote.RemoteTestNG.initAndRun(RemoteTestNG.java:293)
at org.testng.remote.RemoteTestNG.main(RemoteTestNG.java:91)
Caused by: java.lang.IllegalAccessException: class org.testng.internal.InstanceCreator cannot access a member of class practice_selenium.DataProviders with package access
at java.base/jdk.internal.reflect.Reflection.newIllegalAccessException(Reflection.java:394)
at java.base/java.lang.reflect.AccessibleObject.checkAccess(AccessibleObject.java:714)
at java.base/java.lang.reflect.Constructor.newInstanceWithCaller(Constructor.java:495)
at java.base/java.lang.reflect.ReflectAccess.newInstance(ReflectAccess.java:128)
at java.base/jdk.internal.reflect.ReflectionFactory.newInstance(ReflectionFactory.java:304)
at java.base/java.lang.Class.newInstance(Class.java:725)
at org.testng.internal.InstanceCreator.newInstance(InstanceCreator.java:30)
... 26 more
]]>
    </error>
  </testcase> <!-- mainTest -->
  <system-out/>
</testsuite> <!-- practice_selenium.Revision -->
